Workbook

Sheet Tabla
A1: DATOS BASICOS | F1: PRESTACIONES SOCIALES | J1: SEGURIDAD SOCIAL | N1: OTROS | R1: COSTO MENSUAL | S1: COSTO DIARIO | T1: COSTO HORA ORDINARIA
A2: CARGO | B2: BASICO | C2: AUX. TRANS | D2: AUXILIO | E2: TOTAL | F2: CESANTIAS | G2: INT. CENSAN | H2: PRIMA | I2: VACACIONES | J2: ARP | K2: EPS | L2: PENSION | M2: CCF | N2: VIATICOS | O2: ALIMENT | P2: DOTACION | Q2: EXAMENES | V2: DOTACION | W2: OBRA | X2: ADMON | Z2: EXAMENES | AA2: OBRA | AB2: ADMON | AC2: CONDICION
A3: RESIDENTE DE OBRA | B3: 2000000 | C3: 164000 | D3: 1000000 | E3: =+SUM(B3:D3) -> 3164000 | F3: =+(E3-D3)*8.33% -> 180261.2 | G3: =+F3*12% -> 21631.344 | H3: =+(E3-D3)*8.33% -> 180261.2 | I3: =+B3*4.16% -> 83200 | J3: =+B3*6.96% -> 139200 | K3: =+B3*4% -> 80000 | L3: =+B3*12% -> 240000 | M3: =+B3*4% -> 80000 | N3: 0 | O3: 0 | P3: =+$X$13 -> 263900 | Q3: =+$AB$13 -> 115000 | R3: =+SUM(E3:Q3) -> 4547453.7 | S3: =+R3/26 -> 174902.07 | T3: =+S3/8 -> 21862.758 | V3: BOTAS | W3: 128000 | X3: 128000 | Z3: INGRESO | AA3: 20000 | AB3: 20000
A4: ING. SUPERV | B4: 2000000 | C4: 164000 | D4: 700000 | E4: =+SUM(B4:D4) -> 2864000 | F4: =+(E4-D4)*8.33% -> 180261.2 | G4: =+F4*12% -> 21631.344 | H4: =+(E4-D4)*8.33% -> 180261.2 | I4: =+B4*4.16% -> 83200 | J4: =+B4*6.96% -> 139200 | K4: =+B4*4% -> 80000 | L4: =+B4*12% -> 240000 | M4: =+B4*4% -> 80000 | N4: =+$N$12*26 -> 520000 | O4: =+$O$12*26 -> 481000 | P4: =+$X$13 -> 263900 | Q4: =+$AB$13 -> 115000 | R4: =+SUM(E4:Q4) -> 5248453.7 | S4: =+R4/26 -> 201863.61 | T4: =+S4/8 -> 25232.951 | V4: JEANS | W4: =31500*2 -> 63000 | X4: =30000*2 -> 60000 | Z4: OPTOMETRIA | AA4: 16000 | AB4: 16000
A5: SOLDADOR | B5: 2000000 | C5: 164000 | D5: 1000000 | E5: =+SUM(B5:D5) -> 3164000 | F5: =+(E5-D5)*8.33% -> 180261.2 | G5: =+F5*12% -> 21631.344 | H5: =+(E5-D5)*8.33% -> 180261.2 | I5: =+B5*4.16% -> 83200 | J5: =+B5*6.96% -> 139200 | K5: =+B5*4% -> 80000 | L5: =+B5*12% -> 240000 | M5: =+B5*4% -> 80000 | N5: =+$N$12*26 -> 520000 | O5: =+$O$12*26 -> 481000 | P5: =+$W$13 -> 425600 | Q5: =+$AB$13 -> 115000 | R5: =+SUM(E5:Q5) -> 5710153.7 | S5: =+R5/26 -> 219621.3 | T5: =+S5/8 -> 27452.662 | V5: CAMISAS | W5: =45000*2 -> 90000 | X5: =35000*2 -> 70000 | Z5: ESPIROMETRIA | AA5: 16000 | AB5: 16000
A6: TUBERO | B6: 2000000 | C6: 164000 | D6: 800000 | E6: =+SUM(B6:D6) -> 2964000 | F6: =+(E6-D6)*8.33% -> 180261.2 | G6: =+F6*12% -> 21631.344 | H6: =+(E6-D6)*8.33% -> 180261.2 | I6: =+B6*4.16% -> 83200 | J6: =+B6*6.96% -> 139200 | K6: =+B6*4% -> 80000 | L6: =+B6*12% -> 240000 | M6: =+B6*4% -> 80000 | N6: =+$N$12*26 -> 520000 | O6: =+$O$12*26 -> 481000 | P6: =+$W$13 -> 425600 | Q6: =+$AB$13 -> 115000 | R6: =+SUM(E6:Q6) -> 5510153.7 | S6: =+R6/26 -> 211928.99 | T6: =+S6/8 -> 26491.124 | V6: RESPIRADOR | W6: 43600 | Z6: ALTURAS | AA6: 65000 | AB6: 0
A7: PAILERO MONTADOR | B7: 1700000 | C7: 164000 | D7: 300000 | E7: =+SUM(B7:D7) -> 2164000 | F7: =+(E7-D7)*8.33% -> 155271.2 | G7: =+F7*12% -> 18632.544 | H7: =+(E7-D7)*8.33% -> 155271.2 | I7: =+B7*4.16% -> 70720 | J7: =+B7*6.96% -> 118320 | K7: =+B7*4% -> 68000 | L7: =+B7*12% -> 204000 | M7: =+B7*4% -> 68000 | N7: =+$N$12*26 -> 520000 | O7: =+$O$12*26 -> 481000 | P7: =+$W$13 -> 425600 | Q7: =+$AB$13 -> 115000 | R7: =+SUM(E7:Q7) -> 4563814.9 | S7: =+R7/26 -> 175531.34 | T7: =+S7/8 -> 21941.418 | V7: FILTROS | W7: =35800*2 -> 71600 | Z7: ELECTROCARD | AA7: 35000 | AB7: 35000
A8: AYUDANTE | B8: 1300000 | C8: 164000 | D8: 200000 | E8: =+SUM(B8:D8) -> 1664000 | F8: =+(E8-D8)*8.33% -> 121951.2 | G8: =+F8*12% -> 14634.144 | H8: =+(E8-D8)*8.33% -> 121951.2 | I8: =+B8*4.16% -> 54080 | J8: =+B8*6.96% -> 90480 | K8: =+B8*4% -> 52000 | L8: =+B8*12% -> 156000 | M8: =+B8*4% -> 52000 | N8: =+$N$12*26 -> 520000 | O8: =+$O$12*26 -> 481000 | P8: =+$W$13 -> 425600 | Q8: =+$AB$13 -> 115000 | R8: =+SUM(E8:Q8) -> 3868696.5 | S8: =+R8/26 -> 148796.02 | T8: =+S8/8 -> 18599.503 | V8: GUANTES | W8: 11500 | Z8: AUDIOMETRIA | AA8: 8000 | AB8: 8000
A9: SISO | B9: 1700000 | C9: 164000 | D9: 300000 | E9: =+SUM(B9:D9) -> 2164000 | F9: =+(E9-D9)*8.33% -> 155271.2 | G9: =+F9*12% -> 18632.544 | H9: =+(E9-D9)*8.33% -> 155271.2 | I9: =+B9*4.16% -> 70720 | J9: =+B9*6.96% -> 118320 | K9: =+B9*4% -> 68000 | L9: =+B9*12% -> 204000 | M9: =+B9*4% -> 68000 | N9: =+$N$12*26 -> 520000 | O9: =+$O$12*26 -> 481000 | P9: =+$W$13 -> 425600 | Q9: =+$AB$13 -> 115000 | R9: =+SUM(E9:Q9) -> 4563814.9 | S9: =+R9/26 -> 175531.34 | T9: =+S9/8 -> 21941.418 | V9: GAFAS | W9: 4500 | X9: 4500 | Z9: CONFINADOS | AA9: =IF(AC9="SI",80000,0) -> 80000 | AB9: 0 | AC9: SI
V10: TAPAOIDOS | W10: 1400 | X10: 1400 | Z10: THC | AA10: 20000 | AB10: 20000
A11: %UTILIDAD | B11: 0 | M11: VALOR DIA | V11: DELANTAL | W11: 12000
N12: 20000 | O12: 18500
N13: TRANSP | O13: ALIMENT | V13: TOTAL | W13: =SUM(W3:W12) -> 425600 | X13: =SUM(X3:X12) -> 263900 | Z13: TOTAL | AA13: =SUM(AA3:AA12) -> 260000 | AB13: =SUM(AB3:AB12) -> 115000
A14: TABLA DE PRECIOS | I14: VALOR DIA ORDINARIO (8 horas)
A15: CARGO | B15: HORA ORDINARIA | C15: RECARGO NOCTURNO | D15: HORA EXTRA DIURNA | E15: HORA EXTRA NOCTURNA | F15: HORA DOMINICAL | G15: HORA EXTRA DOMINICAL (DIURNA) | H15: HORA EXTRA DOMINICAL (NOCTURNA)
A16: RESIDENTE DE OBRA | B16: =+(($T$3*1)/(1-$B$11)) -> 21862.758 | C16: =+(($T$3*0.35)/(1-$B$11)) -> 7651.9654 | D16: =+(($T$3*1.25)/(1-$B$11)) -> 27328.448 | E16: =+(($T$3*1.75)/(1-$B$11)) -> 38259.827 | F16: =+(($T$3*1.75)/(1-$B$11)) -> 38259.827 | G16: =+(($T$3*2)/(1-$B$11)) -> 43725.517 | H16: =+(($T$3*2.5)/(1-$B$11)) -> 54656.896 | I16: =+B16*8 -> 174902.07
A17: ING. SUPERV | B17: =+(($T$4*1)/(1-$B$11)) -> 25232.951 | C17: =+(($T$4*0.35)/(1-$B$11)) -> 8831.5327 | D17: =+(($T$4*1.25)/(1-$B$11)) -> 31541.188 | E17: =+(($T$4*1.75)/(1-$B$11)) -> 44157.664 | F17: =+(($T$4*1.75)/(1-$B$11)) -> 44157.664 | G17: =+(($T$4*2)/(1-$B$11)) -> 50465.901 | H17: =+(($T$4*2.5)/(1-$B$11)) -> 63082.377 | I17: =+B17*8 -> 201863.61
A18: SOLDADOR | B18: =+(($T$5*1)/(1-$B$11)) -> 27452.662 | C18: =+(($T$5*0.35)/(1-$B$11)) -> 9608.4318 | D18: =+(($T$5*1.25)/(1-$B$11)) -> 34315.828 | E18: =+(($T$5*1.75)/(1-$B$11)) -> 48042.159 | F18: =+(($T$5*1.75)/(1-$B$11)) -> 48042.159 | G18: =+(($T$5*2)/(1-$B$11)) -> 54905.324 | H18: =+(($T$5*2.5)/(1-$B$11)) -> 68631.656 | I18: =+B18*8 -> 219621.3
A19: TUBERO | B19: =+(($T$6*1)/(1-$B$11)) -> 26491.124 | C19: =+(($T$6*0.35)/(1-$B$11)) -> 9271.8933 | D19: =+(($T$6*1.25)/(1-$B$11)) -> 33113.905 | E19: =+(($T$6*1.75)/(1-$B$11)) -> 46359.467 | F19: =+(($T$6*1.75)/(1-$B$11)) -> 46359.467 | G19: =+(($T$6*2)/(1-$B$11)) -> 52982.248 | H19: =+(($T$6*2.5)/(1-$B$11)) -> 66227.809 | I19: =+B19*8 -> 211928.99
A20: PAILERO MONTADOR | B20: =+(($T$7*1)/(1-$B$11)) -> 21941.418 | C20: =+(($T$7*0.35)/(1-$B$11)) -> 7679.4963 | D20: =+(($T$7*1.25)/(1-$B$11)) -> 27426.773 | E20: =+(($T$7*1.75)/(1-$B$11)) -> 38397.482 | F20: =+(($T$7*1.75)/(1-$B$11)) -> 38397.482 | G20: =+(($T$7*2)/(1-$B$11)) -> 43882.836 | H20: =+(($T$7*2.5)/(1-$B$11)) -> 54853.545 | I20: =+B20*8 -> 175531.34
A21: AYUDANTE | B21: =+(($T$8*1)/(1-$B$11)) -> 18599.503 | C21: =+(($T$8*0.35)/(1-$B$11)) -> 6509.8259 | D21: =+(($T$8*1.25)/(1-$B$11)) -> 23249.378 | E21: =+(($T$8*1.75)/(1-$B$11)) -> 32549.13 | F21: =+(($T$8*1.75)/(1-$B$11)) -> 32549.13 | G21: =+(($T$8*2)/(1-$B$11)) -> 37199.005 | H21: =+(($T$8*2.5)/(1-$B$11)) -> 46498.757 | I21: =+B21*8 -> 148796.02
A22: SISO | B22: =+(($T$9*1)/(1-$B$11)) -> 21941.418 | C22: =+(($T$9*0.35)/(1-$B$11)) -> 7679.4963 | D22: =+(($T$9*1.25)/(1-$B$11)) -> 27426.773 | E22: =+(($T$9*1.75)/(1-$B$11)) -> 38397.482 | F22: =+(($T$9*1.75)/(1-$B$11)) -> 38397.482 | G22: =+(($T$9*2)/(1-$B$11)) -> 43882.836 | H22: =+(($T$9*2.5)/(1-$B$11)) -> 54853.545 | I22: =+B22*8 -> 175531.34

Sheet Matriz
B1: CARGO | C1: HORA | D1: VALOR
A2: =CONCATENATE(B2,C2) -> RESIDENTE DE OBRAHORA ORDINARIA | B2: RESIDENTE DE OBRA | C2: HORA ORDINARIA | D2: =VLOOKUP(B2,Tabla!$A$15:$H$22,2,FALSE) -> 21862.758
A3: =CONCATENATE(B3,C3) -> RESIDENTE DE OBRARECARGO NOCTURNO | B3: RESIDENTE DE OBRA | C3: RECARGO NOCTURNO | D3: =VLOOKUP(B3,Tabla!$A$15:$H$22,3,FALSE) -> 7651.9654
A4: =CONCATENATE(B4,C4) -> RESIDENTE DE OBRAHORA EXTRA DIURNA | B4: RESIDENTE DE OBRA | C4: HORA EXTRA DIURNA | D4: =VLOOKUP(B4,Tabla!$A$15:$H$22,4,FALSE) -> 27328.448
A5: =CONCATENATE(B5,C5) -> RESIDENTE DE OBRAHORA EXTRA NOCTURNA | B5: RESIDENTE DE OBRA | C5: HORA EXTRA NOCTURNA | D5: =VLOOKUP(B5,Tabla!$A$15:$H$22,5,FALSE) -> 38259.827
A6: =CONCATENATE(B6,C6) -> RESIDENTE DE OBRAHORA DOMINICAL | B6: RESIDENTE DE OBRA | C6: HORA DOMINICAL | D6: =VLOOKUP(B6,Tabla!$A$15:$H$22,6,FALSE) -> 38259.827
A7: =CONCATENATE(B7,C7) -> RESIDENTE DE OBRAHORA EXTRA DOMINICAL (DIURNA) | B7: RESIDENTE DE OBRA | C7: HORA EXTRA DOMINICAL (DIURNA) | D7: =VLOOKUP(B7,Tabla!$A$15:$H$22,7,FALSE) -> 43725.517
A8: =CONCATENATE(B8,C8) -> RESIDENTE DE OBRAHORA EXTRA DOMINICAL (NOCTURNA) | B8: RESIDENTE DE OBRA | C8: HORA EXTRA DOMINICAL (NOCTURNA) | D8: =VLOOKUP(B8,Tabla!$A$15:$H$22,8,FALSE) -> 54656.896
A9: =CONCATENATE(B9,C9) -> ING. SUPERVHORA ORDINARIA | B9: ING. SUPERV | C9: HORA ORDINARIA | D9: =VLOOKUP(B9,Tabla!$A$15:$H$22,2,FALSE) -> 25232.951
A10: =CONCATENATE(B10,C10) -> ING. SUPERVRECARGO NOCTURNO | B10: ING. SUPERV | C10: RECARGO NOCTURNO | D10: =VLOOKUP(B10,Tabla!$A$15:$H$22,3,FALSE) -> 8831.5327
A11: =CONCATENATE(B11,C11) -> ING. SUPERVHORA EXTRA DIURNA | B11: ING. SUPERV | C11: HORA EXTRA DIURNA | D11: =VLOOKUP(B11,Tabla!$A$15:$H$22,4,FALSE) -> 31541.188
A12: =CONCATENATE(B12,C12) -> ING. SUPERVHORA EXTRA NOCTURNA | B12: ING. SUPERV | C12: HORA EXTRA NOCTURNA | D12: =VLOOKUP(B12,Tabla!$A$15:$H$22,5,FALSE) -> 44157.664
A13: =CONCATENATE(B13,C13) -> ING. SUPERVHORA DOMINICAL | B13: ING. SUPERV | C13: HORA DOMINICAL | D13: =VLOOKUP(B13,Tabla!$A$15:$H$22,6,FALSE) -> 44157.664
A14: =CONCATENATE(B14,C14) -> ING. SUPERVHORA EXTRA DOMINICAL (DIURNA) | B14: ING. SUPERV | C14: HORA EXTRA DOMINICAL (DIURNA) | D14: =VLOOKUP(B14,Tabla!$A$15:$H$22,7,FALSE) -> 50465.901
A15: =CONCATENATE(B15,C15) -> ING. SUPERVHORA EXTRA DOMINICAL (NOCTURNA) | B15: ING. SUPERV | C15: HORA EXTRA DOMINICAL (NOCTURNA) | D15: =VLOOKUP(B15,Tabla!$A$15:$H$22,8,FALSE) -> 63082.377
A16: =CONCATENATE(B16,C16) -> SOLDADORHORA ORDINARIA | B16: SOLDADOR | C16: HORA ORDINARIA | D16: =VLOOKUP(B16,Tabla!$A$15:$H$22,2,FALSE) -> 27452.662
A17: =CONCATENATE(B17,C17) -> SOLDADORRECARGO NOCTURNO | B17: SOLDADOR | C17: RECARGO NOCTURNO | D17: =VLOOKUP(B17,Tabla!$A$15:$H$22,3,FALSE) -> 9608.4318
A18: =CONCATENATE(B18,C18) -> SOLDADORHORA EXTRA DIURNA | B18: SOLDADOR | C18: HORA EXTRA DIURNA | D18: =VLOOKUP(B18,Tabla!$A$15:$H$22,4,FALSE) -> 34315.828
A19: =CONCATENATE(B19,C19) -> SOLDADORHORA EXTRA NOCTURNA | B19: SOLDADOR | C19: HORA EXTRA NOCTURNA | D19: =VLOOKUP(B19,Tabla!$A$15:$H$22,5,FALSE) -> 48042.159
A20: =CONCATENATE(B20,C20) -> SOLDADORHORA DOMINICAL | B20: SOLDADOR | C20: HORA DOMINICAL | D20: =VLOOKUP(B20,Tabla!$A$15:$H$22,6,FALSE) -> 48042.159
A21: =CONCATENATE(B21,C21) -> SOLDADORHORA EXTRA DOMINICAL (DIURNA) | B21: SOLDADOR | C21: HORA EXTRA DOMINICAL (DIURNA) | D21: =VLOOKUP(B21,Tabla!$A$15:$H$22,7,FALSE) -> 54905.324
A22: =CONCATENATE(B22,C22) -> SOLDADORHORA EXTRA DOMINICAL (NOCTURNA) | B22: SOLDADOR | C22: HORA EXTRA DOMINICAL (NOCTURNA) | D22: =VLOOKUP(B22,Tabla!$A$15:$H$22,8,FALSE) -> 68631.656
A23: =CONCATENATE(B23,C23) -> TUBEROHORA ORDINARIA | B23: TUBERO | C23: HORA ORDINARIA | D23: =VLOOKUP(B23,Tabla!$A$15:$H$22,2,FALSE) -> 26491.124
A24: =CONCATENATE(B24,C24) -> TUBERORECARGO NOCTURNO | B24: TUBERO | C24: RECARGO NOCTURNO | D24: =VLOOKUP(B24,Tabla!$A$15:$H$22,3,FALSE) -> 9271.8933
A25: =CONCATENATE(B25,C25) -> TUBEROHORA EXTRA DIURNA | B25: TUBERO | C25: HORA EXTRA DIURNA | D25: =VLOOKUP(B25,Tabla!$A$15:$H$22,4,FALSE) -> 33113.905
A26: =CONCATENATE(B26,C26) -> TUBEROHORA EXTRA NOCTURNA | B26: TUBERO | C26: HORA EXTRA NOCTURNA | D26: =VLOOKUP(B26,Tabla!$A$15:$H$22,5,FALSE) -> 46359.467
A27: =CONCATENATE(B27,C27) -> TUBEROHORA DOMINICAL | B27: TUBERO | C27: HORA DOMINICAL | D27: =VLOOKUP(B27,Tabla!$A$15:$H$22,6,FALSE) -> 46359.467
A28: =CONCATENATE(B28,C28) -> TUBEROHORA EXTRA DOMINICAL (DIURNA) | B28: TUBERO | C28: HORA EXTRA DOMINICAL (DIURNA) | D28: =VLOOKUP(B28,Tabla!$A$15:$H$22,7,FALSE) -> 52982.248
A29: =CONCATENATE(B29,C29) -> TUBEROHORA EXTRA DOMINICAL (NOCTURNA) | B29: TUBERO | C29: HORA EXTRA DOMINICAL (NOCTURNA) | D29: =VLOOKUP(B29,Tabla!$A$15:$H$22,8,FALSE) -> 66227.809
A30: =CONCATENATE(B30,C30) -> PAILERO MONTADORHORA ORDINARIA | B30: PAILERO MONTADOR | C30: HORA ORDINARIA | D30: =VLOOKUP(B30,Tabla!$A$15:$H$22,2,FALSE) -> 21941.418
A31: =CONCATENATE(B31,C31) -> PAILERO MONTADORRECARGO NOCTURNO | B31: PAILERO MONTADOR | C31: RECARGO NOCTURNO | D31: =VLOOKUP(B31,Tabla!$A$15:$H$22,3,FALSE) -> 7679.4963
A32: =CONCATENATE(B32,C32) -> PAILERO MONTADORHORA EXTRA DIURNA | B32: PAILERO MONTADOR | C32: HORA EXTRA DIURNA | D32: =VLOOKUP(B32,Tabla!$A$15:$H$22,4,FALSE) -> 27426.773
A33: =CONCATENATE(B33,C33) -> PAILERO MONTADORHORA EXTRA NOCTURNA | B33: PAILERO MONTADOR | C33: HORA EXTRA NOCTURNA | D33: =VLOOKUP(B33,Tabla!$A$15:$H$22,5,FALSE) -> 38397.482
A34: =CONCATENATE(B34,C34) -> PAILERO MONTADORHORA DOMINICAL | B34: PAILERO MONTADOR | C34: HORA DOMINICAL | D34: =VLOOKUP(B34,Tabla!$A$15:$H$22,6,FALSE) -> 38397.482
A35: =CONCATENATE(B35,C35) -> PAILERO MONTADORHORA EXTRA DOMINICAL (DIURNA) | B35: PAILERO MONTADOR | C35: HORA EXTRA DOMINICAL (DIURNA) | D35: =VLOOKUP(B35,Tabla!$A$15:$H$22,7,FALSE) -> 43882.836
A36: =CONCATENATE(B36,C36) -> PAILERO MONTADORHORA EXTRA DOMINICAL (NOCTURNA) | B36: PAILERO MONTADOR | C36: HORA EXTRA DOMINICAL (NOCTURNA) | D36: =VLOOKUP(B36,Tabla!$A$15:$H$22,8,FALSE) -> 54853.545
A37: =CONCATENATE(B37,C37) -> AYUDANTEHORA ORDINARIA | B37: AYUDANTE | C37: HORA ORDINARIA | D37: =VLOOKUP(B37,Tabla!$A$15:$H$22,2,FALSE) -> 18599.503
A38: =CONCATENATE(B38,C38) -> AYUDANTERECARGO NOCTURNO | B38: AYUDANTE | C38: RECARGO NOCTURNO | D38: =VLOOKUP(B38,Tabla!$A$15:$H$22,3,FALSE) -> 6509.8259
A39: =CONCATENATE(B39,C39) -> AYUDANTEHORA EXTRA DIURNA | B39: AYUDANTE | C39: HORA EXTRA DIURNA | D39: =VLOOKUP(B39,Tabla!$A$15:$H$22,4,FALSE) -> 23249.378
A40: =CONCATENATE(B40,C40) -> AYUDANTEHORA EXTRA NOCTURNA | B40: AYUDANTE | C40: HORA EXTRA NOCTURNA | D40: =VLOOKUP(B40,Tabla!$A$15:$H$22,5,FALSE) -> 32549.13
...

Sheet Cotizacion
A2: Santiago de Cali, 30 de agosto de 2024
A5: Señores:
A6: ASSISTECK
A7: Atn. Ing. Jhon Jairo Galarza
A8: jgalarza@assistech.com.co
E9: COT | F9: 3008-2024
A11: Asunto: Recargo Mano de Obra Jornada Adicional Proyecto Tecnoquimicas
A13: De acuerdo a solicitud nos permitimos presentar propuesta economica que incluye una jornada festiva adicional (01 de septiembre) y la extension de una hora extra por 3 dias ordinarios (30 agosto, 02 y 03 de septiembre)
A15: CANT | B15: CARGO | C15: TIPO | D15: VALOR | E15: HORAS | F15: TOTAL
A16: 4 | B16: TUBERO | C16: HORA DOMINICAL | D16: =VLOOKUP(B16&C16,Matriz!$A$1:$D$50,4,FALSE) -> 46359.467 | E16: 8 | F16: =+A16*D16*E16 -> 1483502.9
A17: 4 | B17: AYUDANTE | C17: HORA DOMINICAL | D17: =VLOOKUP(B17&C17,Matriz!$A$1:$D$50,4,FALSE) -> 32549.13 | E17: 8 | F17: =+A17*D17*E17 -> 1041572.1
A18: 1 | B18: ING. SUPERV | C18: HORA DOMINICAL | D18: =VLOOKUP(B18&C18,Matriz!$A$1:$D$50,4,FALSE) -> 44157.664 | E18: 8 | F18: =+A18*D18*E18 -> 353261.31
A19: 1 | B19: RESIDENTE DE OBRA | C19: HORA DOMINICAL | D19: =VLOOKUP(B19&C19,Matriz!$A$1:$D$50,4,FALSE) -> 38259.827 | E19: 8 | F19: =+A19*D19*E19 -> 306078.62
A20: 1 | B20: SISO | C20: HORA DOMINICAL | D20: =VLOOKUP(B20&C20,Matriz!$A$1:$D$50,4,FALSE) -> 38397.482 | E20: 8 | F20: =+A20*D20*E20 -> 307179.85
A21: 2 | B21: PAILERO MONTADOR | C21: HORA DOMINICAL | D21: =VLOOKUP(B21&C21,Matriz!$A$1:$D$50,4,FALSE) -> 38397.482 | E21: 8 | F21: =+A21*D21*E21 -> 614359.7
A22: 3 | B22: SOLDADOR | C22: HORA DOMINICAL | D22: =VLOOKUP(B22&C22,Matriz!$A$1:$D$50,4,FALSE) -> 48042.159 | E22: 8 | F22: =+A22*D22*E22 -> 1153011.8
A23: 4 | B23: TUBERO | C23: HORA EXTRA DIURNA | D23: =VLOOKUP(B23&C23,Matriz!$A$1:$D$50,4,FALSE) -> 33113.905 | E23: 3 | F23: =+A23*D23*E23 -> 397366.86
A24: 4 | B24: AYUDANTE | C24: HORA EXTRA DIURNA | D24: =VLOOKUP(B24&C24,Matriz!$A$1:$D$50,4,FALSE) -> 23249.378 | E24: 3 | F24: =+A24*D24*E24 -> 278992.54
A25: 1 | B25: ING. SUPERV | C25: HORA EXTRA DIURNA | D25: =VLOOKUP(B25&C25,Matriz!$A$1:$D$50,4,FALSE) -> 31541.188 | E25: 3 | F25: =+A25*D25*E25 -> 94623.565
A26: 1 | B26: RESIDENTE DE OBRA | C26: HORA EXTRA DIURNA | D26: =VLOOKUP(B26&C26,Matriz!$A$1:$D$50,4,FALSE) -> 27328.448 | E26: 3 | F26: =+A26*D26*E26 -> 81985.344
A27: 1 | B27: SISO | C27: HORA EXTRA DIURNA | D27: =VLOOKUP(B27&C27,Matriz!$A$1:$D$50,4,FALSE) -> 27426.773 | E27: 3 | F27: =+A27*D27*E27 -> 82280.318
... A29: 3 | B29: SOLDADOR | C29: HORA EXTRA DIURNA | D29: =VLOOKUP(B29&C29,Matriz!$A$1:$D$50,4,FALSE) -> 34315.828 | E29: 3 | F29: =+A29*D29*E29 -> 308842.45
E31: Total | F31: =SUM(F16:F29) -> 6667618.1
A32: Condiciones Comerciales
A33: 1. | B33: A los anteriores valores agregar el 19% de IVA
A34: 2. | B34: Ejecución una vez recibida la orden de compra
A35: 3. | B35: Pago 30 días fecha factura
A37: Agradezco la atención prestada.
A40: Cordialmente,
A42: Victor Hugo Ortiz Urbano
A43: Ing. Residente
A46: CR 6A 31 – 53 Barrio Porvenir. Teléfono: 382 73 71 Celular: 314 7441501 Cali, Valle Email: gerencia@minduval.com.co
